2018-02-23 12:46:51,311 ERROR: Exception on /reset_password_request [POST] [in c:\users\wendy\desktop\microblog\venv\lib\site-packages\flask\app.py:1560]
Traceback (most recent call last):
  File "c:\users\wendy\desktop\microblog\venv\lib\site-packages\flask\app.py", line 1982, in wsgi_app
    response = self.full_dispatch_request()
  File "c:\users\wendy\desktop\microblog\venv\lib\site-packages\flask\app.py", line 1614, in full_dispatch_request
    rv = self.handle_user_exception(e)
  File "c:\users\wendy\desktop\microblog\venv\lib\site-packages\flask\app.py", line 1517, in handle_user_exception
    reraise(exc_type, exc_value, tb)
  File "c:\users\wendy\desktop\microblog\venv\lib\site-packages\flask\_compat.py", line 33, in reraise
    raise value
  File "c:\users\wendy\desktop\microblog\venv\lib\site-packages\flask\app.py", line 1612, in full_dispatch_request
    rv = self.dispatch_request()
  File "c:\users\wendy\desktop\microblog\venv\lib\site-packages\flask\app.py", line 1598, in dispatch_request
    return self.view_functions[rule.endpoint](**req.view_args)
  File "C:\Users\Wendy\Desktop\microblog\application\routes.py", line 161, in reset_password_request
    send_password_reset_email(user)
  File "C:\Users\Wendy\Desktop\microblog\application\email.py", line 26, in send_password_reset_email
    user=user, token=token))
  File "C:\Users\Wendy\Desktop\microblog\application\email.py", line 16, in send_email
    mail.send(msg)
  File "c:\users\wendy\desktop\microblog\venv\lib\site-packages\flask_mail.py", line 491, in send
    with self.connect() as connection:
  File "c:\users\wendy\desktop\microblog\venv\lib\site-packages\flask_mail.py", line 144, in __enter__
    self.host = self.configure_host()
  File "c:\users\wendy\desktop\microblog\venv\lib\site-packages\flask_mail.py", line 158, in configure_host
    host = smtplib.SMTP(self.mail.server, self.mail.port)
  File "D:\python35\lib\smtplib.py", line 251, in __init__
    (code, msg) = self.connect(host, port)
  File "D:\python35\lib\smtplib.py", line 335, in connect
    self.sock = self._get_socket(host, port, self.timeout)
  File "D:\python35\lib\smtplib.py", line 306, in _get_socket
    self.source_address)
  File "D:\python35\lib\socket.py", line 711, in create_connection
    raise err
  File "D:\python35\lib\socket.py", line 702, in create_connection
    sock.connect(sa)
ConnectionRefusedError: [WinError 10061] 由于目标计算机积极拒绝，无法连接。
2018-02-23 12:47:00,491 ERROR: Exception on /reset_password_request [POST] [in c:\users\wendy\desktop\microblog\venv\lib\site-packages\flask\app.py:1560]
Traceback (most recent call last):
  File "c:\users\wendy\desktop\microblog\venv\lib\site-packages\flask\app.py", line 1982, in wsgi_app
    response = self.full_dispatch_request()
  File "c:\users\wendy\desktop\microblog\venv\lib\site-packages\flask\app.py", line 1614, in full_dispatch_request
    rv = self.handle_user_exception(e)
  File "c:\users\wendy\desktop\microblog\venv\lib\site-packages\flask\app.py", line 1517, in handle_user_exception
    reraise(exc_type, exc_value, tb)
  File "c:\users\wendy\desktop\microblog\venv\lib\site-packages\flask\_compat.py", line 33, in reraise
    raise value
  File "c:\users\wendy\desktop\microblog\venv\lib\site-packages\flask\app.py", line 1612, in full_dispatch_request
    rv = self.dispatch_request()
  File "c:\users\wendy\desktop\microblog\venv\lib\site-packages\flask\app.py", line 1598, in dispatch_request
    return self.view_functions[rule.endpoint](**req.view_args)
  File "C:\Users\Wendy\Desktop\microblog\application\routes.py", line 161, in reset_password_request
    send_password_reset_email(user)
  File "C:\Users\Wendy\Desktop\microblog\application\email.py", line 26, in send_password_reset_email
    user=user, token=token))
  File "C:\Users\Wendy\Desktop\microblog\application\email.py", line 16, in send_email
    mail.send(msg)
  File "c:\users\wendy\desktop\microblog\venv\lib\site-packages\flask_mail.py", line 491, in send
    with self.connect() as connection:
  File "c:\users\wendy\desktop\microblog\venv\lib\site-packages\flask_mail.py", line 144, in __enter__
    self.host = self.configure_host()
  File "c:\users\wendy\desktop\microblog\venv\lib\site-packages\flask_mail.py", line 158, in configure_host
    host = smtplib.SMTP(self.mail.server, self.mail.port)
  File "D:\python35\lib\smtplib.py", line 251, in __init__
    (code, msg) = self.connect(host, port)
  File "D:\python35\lib\smtplib.py", line 335, in connect
    self.sock = self._get_socket(host, port, self.timeout)
  File "D:\python35\lib\smtplib.py", line 306, in _get_socket
    self.source_address)
  File "D:\python35\lib\socket.py", line 711, in create_connection
    raise err
  File "D:\python35\lib\socket.py", line 702, in create_connection
    sock.connect(sa)
ConnectionRefusedError: [WinError 10061] 由于目标计算机积极拒绝，无法连接。
2018-02-23 12:47:37,454 INFO: Microblog startup [in C:\Users\Wendy\Desktop\microblog\application\__init__.py:51]
2018-02-23 12:55:17,548 INFO: Microblog startup [in C:\Users\Wendy\Desktop\microblog\application\__init__.py:51]
2018-02-24 20:45:09,581 INFO: Microblog startup [in C:\Users\Wendy\Desktop\microblog\application\__init__.py:54]
2018-02-24 20:52:28,892 INFO: Microblog startup [in C:\Users\Wendy\Desktop\microblog\application\__init__.py:54]
2018-02-24 20:58:14,683 INFO: Microblog startup [in C:\Users\Wendy\Desktop\microblog\application\__init__.py:54]
2018-02-24 21:05:07,729 INFO: Microblog startup [in C:\Users\Wendy\Desktop\microblog\application\__init__.py:54]
2018-03-04 00:21:38,049 INFO: Microblog startup [in C:\Users\Wendy\Desktop\microblog\application\__init__.py:60]
2018-03-04 00:21:49,669 INFO: Microblog startup [in C:\Users\Wendy\Desktop\microblog\application\__init__.py:60]
2018-03-07 16:41:31,475 INFO: Microblog startup [in C:\Users\Wendy\Desktop\microblog\application\__init__.py:60]
